Workbook

Sheet Sheet1
A2: Three Statement Operating Model: Nike
R3: Year over Year Growth
H4: Actual or Forecast | I4: Actual | J4: Actual | K4: Actual | L4: Forecast | M4: Forecast | N4: Forecast | O4: Forecast | P4: Forecast | R4: =K4 -> Actual | S4: {=L4:P4} -> Forecast | T4: Forecast | U4: Forecast | V4: Forecast | W4: Forecast
A5: Master Error Check Cell | B5: ='Control Panel'!B4 -> 0 | H5: Year | I5: {=_xlfn.SEQUENCE(,8,"2022")} -> 2022 | J5: 2023 | K5: 2024 | L5: 2025 | M5: 2026 | N5: 2027 | O5: 2028 | P5: 2029 | R5: 2024 | S5: 2025 | T5: 2026 | U5: 2027 | V5: 2028 | W5: 2029
A6: Item (in millions) | B6: Assumptions | F6: Notes
A7: Income Statement
A8: Revenues | B8: Stepped Assumption: see note | F8: See note in Assumptions section | I8: 46710 | J8: 51217 | K8: 51362 | L8: =K8*(1+0.5%) -> 51618.81 | M8: =L8*(1+2%) -> 52651.186 | N8: =M8*(1+4%) -> 54757.234 | O8: =N8*(1+5%) -> 57495.095 | P8: =O8*(1+6%) -> 60944.801 | R8: =IFERROR((K8/J8)-1,0) -> 0.0028310912 | S8: =IFERROR((L8/K8)-1,0) -> 0.005 | T8: =IFERROR((M8/L8)-1,0) -> 0.02 | U8: =IFERROR((N8/M8)-1,0) -> 0.04 | V8: =IFERROR((O8/N8)-1,0) -> 0.05 | W8: =IFERROR((P8/O8)-1,0) -> 0.06
A9: Cost of Goods Sold | F9: Revenue - Gross Profit | I9: 25231 | J9: 28925 | K9: 28475 | L9: =L8-L10 -> 29422.722 | M9: =M8-M10 -> 30011.176 | N9: =N8-N10 -> 31211.623 | O9: =O8-O10 -> 32772.204 | P9: =P8-P10 -> 34738.537 | R9: =IFERROR((K9/J9)-1,0) -> -0.015557476 | S9: =IFERROR((L9/K9)-1,0) -> 0.033282588 | T9: =IFERROR((M9/L9)-1,0) -> 0.02 | U9: =IFERROR((N9/M9)-1,0) -> 0.04 | V9: =IFERROR((O9/N9)-1,0) -> 0.05 | W9: =IFERROR((P9/O9)-1,0) -> 0.06
A10: Gross profit | F10: Revenue * Gross Maargin | I10: 21479 | J10: 22292 | K10: 22887 | L10: =L8*L11 -> 22196.088 | M10: =M8*M11 -> 22640.01 | N10: =N8*N11 -> 23545.61 | O10: =O8*O11 -> 24722.891 | P10: =P8*P11 -> 26206.264 | R10: =IFERROR((K10/J10)-1,0) -> 0.02669119 | S10: =IFERROR((L10/K10)-1,0) -> -0.030187954 | T10: =IFERROR((M10/L10)-1,0) -> 0.02 | U10: =IFERROR((N10/M10)-1,0) -> 0.04 | V10: =IFERROR((O10/N10)-1,0) -> 0.05 | W10: =IFERROR((P10/O10)-1,0) -> 0.06
A11: Gross Margin | B11: 0.43 | I11: =I10/I8 -> 0.45983729 | J11: =J10/J8 -> 0.43524611 | K11: =K10/K8 -> 0.44560181 | L11: =$B$11 -> 0.43 | M11: =$B$11 -> 0.43 | N11: =$B$11 -> 0.43 | O11: =$B$11 -> 0.43 | P11: =$B$11 -> 0.43
A13: SG&A Expenses | B13: 0.26 | F13: 26% of Total SG&A
A14: Demand creation expense | B14: 0.74 | F14: 74% of Total SG&A | I14: 3850 | J14: 4060 | K14: 4285 | L14: =L16*$B$13 -> 4253.5402 | M14: =M16*$B$13 -> 4338.611 | N14: =N16*$B$13 -> 4512.1555 | O14: =O16*$B$13 -> 4737.7633 | P14: =P16*$B$13 -> 5022.0291 | R14: =IFERROR((K14/J14)-1,0) -> 0.055418719 | S14: =IFERROR((L14/K14)-1,0) -> -0.0073418351 | T14: =IFERROR((M14/L14)-1,0) -> 0.02 | U14: =IFERROR((N14/M14)-1,0) -> 0.04 | V14: =IFERROR((O14/N14)-1,0) -> 0.05 | W14: =IFERROR((P14/O14)-1,0) -> 0.06
A15: Operating overhead expense | I15: 10954 | J15: 12317 | K15: 12291 | L15: =L16*$B$14 -> 12106.23 | M15: =M16*$B$14 -> 12348.355 | N15: =N16*$B$14 -> 12842.289 | O15: =O16*$B$14 -> 13484.403 | P15: =P16*$B$14 -> 14293.467 | R15: =IFERROR((K15/J15)-1,0) -> -0.0021109036 | S15: =IFERROR((L15/K15)-1,0) -> -0.015032959 | T15: =IFERROR((M15/L15)-1,0) -> 0.02 | U15: =IFERROR((N15/M15)-1,0) -> 0.04 | V15: =IFERROR((O15/N15)-1,0) -> 0.05 | W15: =IFERROR((P15/O15)-1,0) -> 0.06
A16: Total selling and administrative expense | B16: =I16/I8 -> 0.31693428 | F16: Revenue * Assumption | I16: 14804 | J16: 16377 | K16: 16576 | L16: =L8*$B$16 -> 16359.77 | M16: =M8*$B$16 -> 16686.966 | N16: =N8*$B$16 -> 17354.444 | O16: =O8*$B$16 -> 18222.166 | P16: =P8*$B$16 -> 19315.496 | R16: =IFERROR((K16/J16)-1,0) -> 0.012151188 | S16: =IFERROR((L16/K16)-1,0) -> -0.013044755 | T16: =IFERROR((M16/L16)-1,0) -> 0.02 | U16: =IFERROR((N16/M16)-1,0) -> 0.04 | V16: =IFERROR((O16/N16)-1,0) -> 0.05 | W16: =IFERROR((P16/O16)-1,0) -> 0.06
A18: EBIT (Operating Income) | I18: =I10-I16 -> 6675 | J18: =J10-J16 -> 5915 | K18: =K10-K16 -> 6311 | L18: =L10-L16 -> 5836.3182 | M18: =M10-M16 -> 5953.0445 | N18: =N10-N16 -> 6191.1663 | O18: =O10-O16 -> 6500.7246 | P18: =P10-P16 -> 6890.7681 | R18: =IFERROR((K18/J18)-1,0) -> 0.066948436 | S18: =IFERROR((L18/K18)-1,0) -> -0.075214996 | T18: =IFERROR((M18/L18)-1,0) -> 0.02 | U18: =IFERROR((N18/M18)-1,0) -> 0.04 | V18: =IFERROR((O18/N18)-1,0) -> 0.05 | W18: =IFERROR((P18/O18)-1,0) -> 0.06
A19: Interest | I19: 205 | J19: -6 | K19: -161 | L19: -161 | M19: -161 | N19: -161 | O19: -161 | P19: -161 | R19: =IFERROR((K19/J19)-1,0) -> 25.833333 | S19: =IFERROR((L19/K19)-1,0) -> 0 | T19: =IFERROR((M19/L19)-1,0) -> 0 | U19: =IFERROR((N19/M19)-1,0) -> 0 | V19: =IFERROR((O19/N19)-1,0) -> 0 | W19: =IFERROR((P19/O19)-1,0) -> 0
A20: Other (income) expense, net | I20: -181 | J20: -280 | K20: -228 | L20: -228 | M20: -228 | N20: -228 | O20: -228 | P20: -228 | R20: =IFERROR((K20/J20)-1,0) -> -0.18571429 | S20: =IFERROR((L20/K20)-1,0) -> 0 | T20: =IFERROR((M20/L20)-1,0) -> 0 | U20: =IFERROR((N20/M20)-1,0) -> 0 | V20: =IFERROR((O20/N20)-1,0) -> 0 | W20: =IFERROR((P20/O20)-1,0) -> 0
A21: Income before income taxes | I21: =I18-I19-I20 -> 6651 | J21: =J18-J19-J20 -> 6201 | K21: =K18-K19-K20 -> 6700 | L21: =L18-L19-L20 -> 6225.3182 | M21: =M18-M19-M20 -> 6342.0445 | N21: =N18-N19-N20 -> 6580.1663 | O21: =O18-O19-O20 -> 6889.7246 | P21: =P18-P19-P20 -> 7279.7681 | R21: =IFERROR((K21/J21)-1,0) -> 0.080470892 | S21: =IFERROR((L21/K21)-1,0) -> -0.070848036 | T21: =IFERROR((M21/L21)-1,0) -> 0.018750265 | U21: =IFERROR((N21/M21)-1,0) -> 0.037546533 | V21: =IFERROR((O21/N21)-1,0) -> 0.047044148 | W21: =IFERROR((P21/O21)-1,0) -> 0.056612346
A22: Income tax expense | B22: 0.15 | F22: Percent of Operating Income | I22: 605 | J22: 1131 | K22: 1000 | L22: =L21*$B$22 -> 933.79772 | M22: =M21*$B$22 -> 951.30668 | N22: =N21*$B$22 -> 987.02495 | O22: =O21*$B$22 -> 1033.4587 | P22: =P21*$B$22 -> 1091.9652 | R22: =IFERROR((K22/J22)-1,0) -> -0.1158267 | S22: =IFERROR((L22/K22)-1,0) -> -0.066202276 | T22: =IFERROR((M22/L22)-1,0) -> 0.018750265 | U22: =IFERROR((N22/M22)-1,0) -> 0.037546533 | V22: =IFERROR((O22/N22)-1,0) -> 0.047044148 | W22: =IFERROR((P22/O22)-1,0) -> 0.056612346
A23: Net income | I23: 6046 | J23: 5070 | K23: 5700 | L23: =L21-L22 -> 5291.5204 | M23: =M21-M22 -> 5390.7378 | N23: =N21-N22 -> 5593.1414 | O23: =O21-O22 -> 5856.2659 | P23: =P21-P22 -> 6187.8029 | R23: =IFERROR((K23/J23)-1,0) -> 0.12426036 | S23: =IFERROR((L23/K23)-1,0) -> -0.071663081 | T23: =IFERROR((M23/L23)-1,0) -> 0.018750265 | U23: =IFERROR((N23/M23)-1,0) -> 0.037546533 | V23: =IFERROR((O23/N23)-1,0) -> 0.047044148 | W23: =IFERROR((P23/O23)-1,0) -> 0.056612346
A24: Margin | I24: =I23/I8 -> 0.12943695 | J24: =J23/J8 -> 0.09899057 | K24: =K23/K8 -> 0.11097699 | L24: =L23/L8 -> 0.10251148 | M24: =M23/M8 -> 0.10238588 | N24: =N23/N8 -> 0.10214434 | O24: =O23/O8 -> 0.10185679 | P24: =P23/P8 -> 0.10153127
A26: EBITDA, as Defined
A27: Net Income | I27: {=I23:K23} -> 6046 | J27: 5070 | K27: 5700 | L27: =L23 -> 5291.5204 | M27: =M23 -> 5390.7378 | N27: =N23 -> 5593.1414 | O27: =O23 -> 5856.2659 | P27: =P23 -> 6187.8029 | R27: =IFERROR((K27/J27)-1,0) -> 0.12426036 | S27: =IFERROR((L27/K27)-1,0) -> -0.071663081 | T27: =IFERROR((M27/L27)-1,0) -> 0.018750265 | U27: =IFERROR((N27/M27)-1,0) -> 0.037546533 | V27: =IFERROR((O27/N27)-1,0) -> 0.047044148 | W27: =IFERROR((P27/O27)-1,0) -> 0.056612346
A28: Interest | I28: 205 | J28: -6 | K28: -161 | L28: =L19 -> -161 | M28: =M19 -> -161 | N28: =N19 -> -161 | O28: =O19 -> -161 | P28: =P19 -> -161 | R28: =IFERROR((K28/J28)-1,0) -> 25.833333 | S28: =IFERROR((L28/K28)-1,0) -> 0 | T28: =IFERROR((M28/L28)-1,0) -> 0 | U28: =IFERROR((N28/M28)-1,0) -> 0 | V28: =IFERROR((O28/N28)-1,0) -> 0 | W28: =IFERROR((P28/O28)-1,0) -> 0
A29: Income tax expense | I29: 605 | J29: 1131 | K29: 1000 | L29: =L22 -> 933.79772 | M29: =M22 -> 951.30668 | N29: =N22 -> 987.02495 | O29: =O22 -> 1033.4587 | P29: =P22 -> 1091.9652 | R29: =IFERROR((K29/J29)-1,0) -> -0.1158267 | S29: =IFERROR((L29/K29)-1,0) -> -0.066202276 | T29: =IFERROR((M29/L29)-1,0) -> 0.018750265 | U29: =IFERROR((N29/M29)-1,0) -> 0.037546533 | V29: =IFERROR((O29/N29)-1,0) -> 0.047044148 | W29: =IFERROR((P29/O29)-1,0) -> 0.056612346
A30: Depreciation | I30: 717 | J30: 703 | K30: 796 | L30: =L177 -> 856.42857 | M30: =M177 -> 916.85714 | N30: =N177 -> 977.28571 | O30: =O177 -> 1037.7143 | P30: =P177 -> 1098.1429 | R30: =IFERROR((K30/J30)-1,0) -> 0.13229018 | S30: =IFERROR((L30/K30)-1,0) -> 0.075915291 | T30: =IFERROR((M30/L30)-1,0) -> 0.070558799 | U30: =IFERROR((N30/M30)-1,0) -> 0.065908383 | V30: =IFERROR((O30/N30)-1,0) -> 0.061833065 | W30: =IFERROR((P30/O30)-1,0) -> 0.058232379
A31: Amortization | I31: 123 | J31: 156 | K31: 48 | L31: 48 | M31: 48 | N31: 48 | O31: 48 | P31: 48
A32: Toal EBITDA Adjustments | I32: =SUM(I28:I31) -> 1650 | J32: =SUM(J28:J31) -> 1984 | K32: =SUM(K28:K31) -> 1683 | L32: =SUM(L28:L31) -> 1677.2263 | M32: =SUM(M28:M31) -> 1755.1638 | N32: =SUM(N28:N31) -> 1851.3107 | O32: =SUM(O28:O31) -> 1958.173 | P32: =SUM(P28:P31) -> 2077.1081 | R32: =IFERROR((K32/J32)-1,0) -> -0.15171371 | S32: =IFERROR((L32/K32)-1,0) -> -0.0034306028 | T32: =IFERROR((M32/L32)-1,0) -> 0.046468104 | U32: =IFERROR((N32/M32)-1,0) -> 0.05477941 | V32: =IFERROR((O32/N32)-1,0) -> 0.057722521 | W32: =IFERROR((P32/O32)-1,0) -> 0.060737787
A33: EBITDA, as Defined | I33: =I27+I32 -> 7696 | J33: =J27+J32 -> 7054 | K33: =K27+K32 -> 7383 | L33: =L27+L32 -> 6968.7467 | M33: =M27+M32 -> 7145.9017 | N33: =N27+N32 -> 7444.452 | O33: =O27+O32 -> 7814.4389 | P33: =P28+P32 -> 1916.1081 | R33: =IFERROR((K33/J33)-1,0) -> 0.046640204 | S33: =IFERROR((L33/K33)-1,0) -> -0.056109071 | T33: =IFERROR((M33/L33)-1,0) -> 0.025421348 | U33: =IFERROR((N33/M33)-1,0) -> 0.041779242 | V33: =IFERROR((O33/N33)-1,0) -> 0.04969968 | W33: =IFERROR((P33/O33)-1,0) -> -0.75479902
A34: Margin | I34: =I33/I9 -> 0.3050216 | J34: =J33/J9 -> 0.24387208 | K34: =K33/K9 -> 0.25928007 | L34: =L33/L9 -> 0.23684915 | M34: =M33/M9 -> 0.23810802 | N34: =N33/N9 -> 0.23851538 | O34: =O33/O9 -> 0.23844716 | P34: =P33/P9 -> 0.055157996
A36: Balance Sheet
A37: Assets
A38: Current Assets:
A39: Cash and equivalents | I39: 8574 | J39: 7441 | K39: 9860 | L39: {=L127:P127} -> 10296.25 | M39: 10555.851 | N39: 10831.81 | O39: 11286.283 | P39: 12969.308 | R39: =IFERROR((K39/J39)-1,0) -> 0.32509071 | S39: =IFERROR((L39/K39)-1,0) -> 0.044244435 | T39: =IFERROR((M39/L39)-1,0) -> 0.025213161 | U39: =IFERROR((N39/M39)-1,0) -> 0.026142786 | V39: =IFERROR((O39/N39)-1,0) -> 0.041957176 | W39: =IFERROR((P39/O39)-1,0) -> 0.14912134
A40: Short-term investments | F40: Held Flat for Forecast | I40: 4423 | J40: 3234 | K40: 1722 | L40: 1722 | M40: 1722 | N40: 1722 | O40: 1722 | P40: 1722 | R40: =IFERROR((K40/J40)-1,0) -> -0.46753247 | S40: =IFERROR((L40/K40)-1,0) -> 0 | T40: =IFERROR((M40/L40)-1,0) -> 0 | U40: =IFERROR((N40/M40)-1,0) -> 0 | V40: =IFERROR((O40/N40)-1,0) -> 0 | W40: =IFERROR((P40/O40)-1,0) -> 0
A41: Accounts receivable, net | F41: See Networking Capital Schedule | I41: 4667 | J41: 4131 | K41: 4427 | L41: =L134 -> 4384.0633 | M41: =M134 -> 4471.7446 | N41: =N134 -> 4650.6144 | O41: =O134 -> 4883.1451 | P41: =P134 -> 5176.1338 | R41: =IFERROR((K41/J41)-1,0) -> 0.071653353 | S41: =IFERROR((L41/K41)-1,0) -> -0.009698822 | T41: =IFERROR((M41/L41)-1,0) -> 0.02 | U41: =IFERROR((N41/M41)-1,0) -> 0.04 | V41: =IFERROR((O41/N41)-1,0) -> 0.05 | W41: =IFERROR((P41/O41)-1,0) -> 0.06
A42: Inventories | F42: See Networking Capital Schedule | I42: 8420 | J42: 8454 | K42: 7519 | L42: =L135 -> 8423.7655 | M42: =M135 -> 8592.2408 | N42: =N135 -> 8935.9305 | O42: =O135 -> 9382.727 | P42: =P135 -> 9945.6906 | R42: =IFERROR((K42/J42)-1,0) -> -0.11059853 | S42: =IFERROR((L42/K42)-1,0) -> 0.12033057 | T42: =IFERROR((M42/L42)-1,0) -> 0.02 | U42: =IFERROR((N42/M42)-1,0) -> 0.04 | V42: =IFERROR((O42/N42)-1,0) -> 0.05 | W42: =IFERROR((P42/O42)-1,0) -> 0.06
A43: Prepaid expenses and other current assets | F43: See Networking Capital Schedule | I43: 2129 | J43: 1942 | K43: 1854 | L43: =L136 -> 2064.7524 | M43: =M136 -> 2106.0474 | N43: =N136 -> 2190.2893 | O43: =O136 -> 2299.8038 | P43: =P136 -> 2437.792 | R43: =IFERROR((K43/J43)-1,0) -> -0.045314109 | S43: =IFERROR((L43/K43)-1,0) -> 0.11367443 | T43: =IFERROR((M43/L43)-1,0) -> 0.02 | U43: =IFERROR((N43/M43)-1,0) -> 0.04 | V43: =IFERROR((O43/N43)-1,0) -> 0.05 | W43: =IFERROR((P43/O43)-1,0) -> 0.06
A45: Total current assets | I45: 28213 | J45: 25202 | K45: 25382 | L45: =SUM(L39:L44) -> 26890.831 | M45: =SUM(M39:M44) -> 27447.884 | N45: =SUM(N39:N44) -> 28330.645 | O45: =SUM(O39:O44) -> 29573.959 | P45: =SUM(P39:P44) -> 32250.925 | R45: =IFERROR((K45/J45)-1,0) -> 0.0071422903 | S45: =IFERROR((L45/K45)-1,0) -> 0.059444936 | T45: =IFERROR((M45/L45)-1,0) -> 0.020715337 | U45: =IFERROR((N45/M45)-1,0) -> 0.032161338 | V45: =IFERROR((O45/N45)-1,0) -> 0.043885831 | W45: =IFERROR((P45/O45)-1,0) -> 0.090517682
A47: Long-term assets:
...

Sheet Control Panel
B2: Error Checking
B4: =SUM(B6:B13) -> 0 | C4: Master Error Check Cell
B6: =SUM(Sheet1!I86:Q86) -> 0 | C6: Balance sheet doesn't balance
B7: =SUM(Sheet1!I128:Q128) -> 0 | C7: Statement of Cash Flows doesn't match the Balance Sheet
B8: =SUM(Sheet1!I151:P151) -> 0 | C8: Tax Accrual schedule doesn't match the Balance Sheet
B9: =SUM(Sheet1!I159:P159) -> 0 | C9: PP&E Schedule doesn't match Balance Sheet
B10: =SUM(Sheet1!I165:P165) -> 0 | C10: CapEx Forecast doesn't match Statement of Cash Flows
B11: =SUM(Sheet1!I178:P178) -> 0 | C11: Depriciation Schedule doesn't match Balance Sheet
B12: =SUM(Sheet1!K186:P186) -> 0 | C12: Term Debt doesn't match Balance Sheet
B13: =SUM(Sheet1!K198:P198) -> 0 | C13: Maturity Schedule doesn't match Term Debt
C15: Put all errors above this line
B17: Formatting Guide
B18: What it looks like | C18: What it means
B19: 1000 | C19: Blue font, no shading = hardcoded actual
B20: 1000 | C20: Black font, no shading = formula
C21: Bright yellow shading = work in progress
B22: 1000 | C22: Red font, no shading = error checking cell
C23: Gray shading = deliberately left blank
B24: 1000 | C24: Blue font, light yellow shading = input or assumption
B25: 1000 | C25: Green font, no shading = info comes from another tab or workbook
B26: 1000 | C26: Orange shading = unique formula or cell
